Workbook

Sheet Case Overview
B2: NYKAA IPO ANALYSIS
B4: Market Hype or Financial Reality?
D5: A Five-Year Post-IPO Financial Review (FY2022–FY2026)
B7: Project Information | F7: Business Context | K7: Business QUESTION
B8: Item | C8: Details | F8: Nykaa entered the public markets in 2021 as one of India's most successful consumer-tech IPOs. Strong revenue growth, a trusted beauty brand, and increasing digital adoption created high investor expectations. This project reviews Nykaa's financial performance from FY2022 to FY2025 to assess whether the premium valuation assigned during its IPO was ultimately supported by business fundamentals. | K8: Did Nykaa's financial performance justify the premium valuation investors paid during its IPO?
B9: Company | C9: Nykaa
B10: Industry | C10: Beauty & Lifestyle
B11: Project Type | C11: Equity Research Case Study
B12: Period | C12: FY22–FY26
B13: Currency | C13: INR
B15: Objectives | F15: KPIs | K15: Scope
B16: • Analyze revenue growth • Evaluate profitability • Study cash flow trends • Compare IPO expectations with actual performance • Form an investment conclusion | F16: Growth | H16: Profitability | K16: Included | L16: Excluded
F17: Revenue Growth | H17: Net Margin | K17: •Financial Statements •Trend Analysis •Ratio Analysis •Dashboard | L17: •DCF Valuation •Forecasting •Stock Analysis •Technical Analysis
F18: Revenue CAGR | H18: ROE
F19: Asset Growth | H19: ROA
F20: Operating Cash Flow | H20: Debt to Equity
B22: Methodology | D22: Research → Collect → Analyze → Visualize → Recommend
B24: Workbook Guide | D24: Sheet | F24: Overview | G24: Financial Data | I24: Financial Analysis | K24: Dashboard | L24: Sources & Notes
D25: Purpose | F25: Project Summary | G25: Historical Statements | I25: KPI & Ratio Analysis | K25: Insights | L25: References

Sheet Financial Data
B2: NYKAA IPO ANALYSIS
B4: Raw Financial Data (Summary of Financial Statements)
B6: Figures in Rs. Crores
B8: Statement of Profit & Loss | I8: Source: Annual Reports (FY22–FY26) Cross-verified using Screener & Groww.
B9: Particulars | C9: FY21-22 | D9: FY22-23 | E9: FY23-24 | F9: FY24-25 | G9: FY25-26
B10: Revenue from Operations | C10: 3774 | D10: 5144 | E10: 6386 | F10: 7950 | G10: 10022
B11: Other Income | C11: 27 | D11: 30 | E11: 30 | F11: 27 | G11: 15
B12: Total Income | C12: 3801 | D12: 5174 | E12: 6416 | F12: 7977 | G12: 10037
B13: EBITDA* | C13: 190.23 | D13: 286.26 | E13: 376.09 | F13: 501.17 | G13: —
B14: Operating Profit (EBIT) | C14: 164 | D14: 257 | E14: 347 | F14: 475 | G14: 752
B15: Finance Cost | C15: 47 | D15: 76 | E15: 84 | F15: 108 | G15: 117
B16: Depreciation & Amortization | C16: 96 | D16: 173 | E16: 224 | F16: 266 | G16: 320
B17: Profit Before Tax | C17: 47 | D17: 38 | E17: 69 | F17: 127 | G17: 330
B18: Profit After Tax (PAT) | C18: 41 | D18: 21 | E18: 40 | F18: 72 | G18: 204
B19: EPS | C19: 0.14 | D19: 0.07 | E19: 0.11 | F19: 0.23 | G19: 0.7
B20: *FY25-26 EBITDA not available in public summary sources.
B22: Balance Sheet
B23: Particulars | C23: FY21-22 | D23: FY22-23 | E23: FY23-24 | F23: FY24-25 | G23: FY25-26
B24: Cash & Cash Equivalents | C24: 267 | D24: 149 | E24: 240 | F24: 217 | G24: —
B25: Trade Receivables | C25: 95 | D25: 164 | E25: 242 | F25: 247 | G25: —
B26: Inventories | C26: 876 | D26: 1005 | E26: 1192 | F26: 1418 | G26: —
B27: Other Current Assets | C27: 690 | D27: 588 | E27: 620 | F27: 796 | G27: —
B28: Total Current Assets | C28: 1927 | D28: 1906 | E28: 2293 | F28: 2677 | G28: —
B29: Property, Plant & Equipment | C29: 382 | D29: 545 | E29: 503 | F29: 605 | G29: —
B30: Other Non-Current Assets | C30: 719 | D30: 1044 | E30: 1108 | F30: 1302 | G30: —
B31: Total Assets | C31: 2646 | D31: 2950 | E31: 3401 | F31: 3980 | G31: 4611
B32: Trade Payables | C32: 362 | D32: 265 | E32: 387 | F32: 635 | G32: —
B33: Borrowings | C33: 593 | D33: 798 | E33: 969 | F33: 1321 | G33: 1238
B34: Other Liabilities | C34: 714 | D34: 773 | E34: 1169 | F34: 1358 | G34: 1936
B35: Total Liabilities | C35: 2646 | D35: 2950 | E35: 3401 | F35: 3980 | G35: 4611
B36: Equity Share Capital | C36: 47 | D36: 285 | E36: 286 | F36: 286 | G36: 286
B37: Other Equity (Reserves) | C37: 1292 | D37: 1093 | E37: 977 | F37: 1015 | G37: 1152
B38: Total Equity | C38: =C36+C37 -> 1339 | D38: =D36+D37 -> 1378 | E38: =E36+E37 -> 1263 | F38: =F36+F37 -> 1301 | G38: =G36+G37 -> 1438
B40: Cash Flow Statement
B41: Particulars | C41: FY21-22 | D41: FY22-23 | E41: FY23-24 | F41: FY24-25 | G41: FY25-26
B42: Opening Cash Balance | C42: 67 | D42: 37 | E42: 41 | F42: 76 | G42: 125
B43: Cash Flow from Operating Activities | C43: -354 | D43: -140 | E43: 0 | F43: 467 | G43: 644
B44: Cash Flow from Investing Activities | C44: -603 | D44: 140 | E44: -10 | F44: -205 | G44: -159
B45: Cash Flow from Financing Activities | C45: 927 | D45: 5 | E45: 44 | F45: -212 | G45: -433
B46: Net Increase / (Decrease) in Cash | C46: -30 | D46: 4 | E46: 34 | F46: 49 | G46: 52
...

Sheet Financial Analysis
B2: NYKAA IPO ANALYSIS
B4: Financial Performance Review
AA5: Year | AB5: Revenue Growth | AD5: Year | AE5: Operating CF | AF5: Free CF
B6: Growth Analysis | J6: Overall Performance Assessment | AA6: FY23 | AB6: 0.363 | AD6: FY22 | AE6: -354 | AF6: -448
B7: Metric | D7: FY22 | E7: FY23 | F7: FY24 | G7: FY25 | H7: FY26 | J7: Area | L7: Assessment | AA7: FY24 | AB7: 0.2414 | AD7: FY23 | AE7: -140 | AF7: -348
B8: Revenue Growth % | D8: N/A | E8: =('Financial Data'!D10-'Financial Data'!C10)/'Financial Data'!C10 -> 0.36301007 | F8: =('Financial Data'!E10-'Financial Data'!D10)/'Financial Data'!D10 -> 0.24144635 | G8: =('Financial Data'!F10-'Financial Data'!E10)/'Financial Data'!E10 -> 0.24491074 | H8: =('Financial Data'!G10-'Financial Data'!F10)/'Financial Data'!F10 -> 0.26062893 | J8: Revenue Growth | L8: =IF(AVERAGE(C8:G8)>0.2,"Strong"," Moderate") -> Strong | O8: Note: | AA8: FY25 | AB8: 0.2449 | AD8: FY24 | AE8: 0 | AF8: -110
B9: Revenue CAGR | D9: =('Financial Data'!G10/'Financial Data'!C10)^(1/5)-1 -> 0.21571143 | J9: Profitability | L9: =IF(G15>5%," Improving"," Stable") -> Stable | O9: All financial figures are linked directly from the Financial Data worksheet. All ratios and performance metrics are calculated using Excel formulas. Business assessments are based on the calculated results. | AA9: FY26 | AB9: 0.2606 | AD9: FY25 | AE9: 467 | AF9: 339
B10: Asset Growth % | D10: N/A | E10: =('Financial Data'!D31-'Financial Data'!C31)/'Financial Data'!D31 -> 0.10305085 | F10: =('Financial Data'!E31-'Financial Data'!D31)/'Financial Data'!E31 -> 0.13260806 | G10: =('Financial Data'!F31-'Financial Data'!E31)/'Financial Data'!F31 -> 0.14547739 | H10: =('Financial Data'!G31-'Financial Data'!F31)/'Financial Data'!G31 -> 0.13684667 | J10: Cash Flow | L10: =IF(G22>0,"Positive","Weak") -> Positive | AD10: FY26 | AE10: 644 | AF10: 493
J11: Financial Position | L11: =IF(G24<1,"Healthy","Moderate") -> Healthy | Z11: Year | AA11: Operating Margin | AB11: Net Margin
B12: Profitability Analysis | J12: Overall Performance | L12: =IF(COUNTIF(L8:M11,"*")>=3,"Positive","Mixed") -> Positive | Z12: FY22 | AA12: 0.0435 | AB12: 0.0109
B13: Metric | D13: FY22 | E13: FY23 | F13: FY24 | G13: FY25 | H13: FY26 | Z13: FY23 | AA13: 0.05 | AB13: 0.0041
B14: Operating Margin % | D14: ='Financial Data'!C14/'Financial Data'!C10 -> 0.04345522 | E14: ='Financial Data'!D14/'Financial Data'!D10 -> 0.04996112 | F14: ='Financial Data'!E14/'Financial Data'!E10 -> 0.054337614 | G14: ='Financial Data'!F14/'Financial Data'!F10 -> 0.059748428 | H14: ='Financial Data'!G14/'Financial Data'!G10 -> 0.075034923 | Z14: FY24 | AA14: 0.0543 | AB14: 0.0063
B15: Net Profit Margin % | D15: ='Financial Data'!C18/'Financial Data'!C10 -> 0.010863805 | E15: ='Financial Data'!D18/'Financial Data'!D10 -> 0.0040824261 | F15: ='Financial Data'!E18/'Financial Data'!E10 -> 0.0062637018 | G15: ='Financial Data'!F18/'Financial Data'!F10 -> 0.0090566038 | H15: ='Financial Data'!G18/'Financial Data'!G10 -> 0.020355219 | Z15: FY25 | AA15: 0.0597 | AB15: 0.0091
B16: ROA % | D16: ='Financial Data'!C18/'Financial Data'!C31 -> 0.015495087 | E16: ='Financial Data'!D18/'Financial Data'!D31 -> 0.0071186441 | F16: ='Financial Data'!E18/'Financial Data'!E31 -> 0.011761247 | G16: ='Financial Data'!F18/'Financial Data'!F31 -> 0.018090452 | H16: ='Financial Data'!G18/'Financial Data'!G31 -> 0.04424203 | J16: Market Performance vs Business Performance | Z16: FY26 | AA16: 0.075 | AB16: 0.0204
B17: ROE % | D17: ='Financial Data'!C18/('Financial Data'!C36+'Financial Data'!C37) -> 0.030619866 | E17: ='Financial Data'!D18/('Financial Data'!D36+'Financial Data'!D37) -> 0.015239478 | F17: ='Financial Data'!E18/('Financial Data'!E36+'Financial Data'!E37) -> 0.031670625 | G17: ='Financial Data'!F18/('Financial Data'!F36+'Financial Data'!F37) -> 0.055342045 | H17: ='Financial Data'!G18/('Financial Data'!G36+'Financial Data'!G37) -> 0.1418637 | J17: Metric | M17: Value
J18: IPO Issue Price (2021) | M18: 1125
B19: Cash Flow & Financial Position | J19: Current Share Price (2026) | M19: 314.4
B20: Metric | D20: FY22 | E20: FY23 | F20: FY24 | G20: FY25 | H20: FY26 | J20: Price Change | M20: =(M19-M18)/M18 -> -0.72053333
B21: Operating Cash Flow | D21: ='Financial Data'!C43 -> -354 | E21: ='Financial Data'!D43 -> -140 | F21: ='Financial Data'!E43 -> 0 | G21: ='Financial Data'!F43 -> 467 | H21: ='Financial Data'!G43 -> 644
B22: Free Cash Flow | D22: ='Financial Data'!C48 -> -448 | E22: ='Financial Data'!D48 -> -348 | F22: ='Financial Data'!E48 -> -110 | G22: ='Financial Data'!F48 -> 339 | H22: ='Financial Data'!G48 -> 493
B23: Debt-to-Equity | D23: ='Financial Data'!C33/'Financial Data'!C38 -> 0.44286781 | E23: ='Financial Data'!D33/'Financial Data'!D38 -> 0.57910015 | F23: ='Financial Data'!E33/'Financial Data'!E38 -> 0.7672209 | G23: ='Financial Data'!F33/'Financial Data'!F38 -> 1.0153728 | H23: ='Financial Data'!G33/'Financial Data'!G38 -> 0.86091794

Sheet Dashboards
B2: NYKAA IPO ANALYSIS
B4: Financial Performance Dashboards
B5: Figures in Rs. Crores
B7: REVENUE | D7: NET PROFIT | F7: REVENUE CAGR | I7: OPERATING MARGIN | L7: FREE CASH FLOW | O7: Insights
B8: ='Financial Data'!G10 -> 10022 | D8: ='Financial Data'!G18 -> 204 | F8: ='Financial Analysis'!D9 -> 0.21571143 | I8: ='Financial Analysis'!H14 -> 0.075034923 | L8: ='Financial Analysis'!H22 -> 493 | O8: • Revenue increased from ₹3,774 Cr to ₹10,022 Cr, delivering a 21.6% CAGR. • Operating margin improved from 4.35% to 7.50%. • Cash flow turned positive by FY25. • Net profit reached ₹204 Cr in FY26. • Overall financial performance improved significantly during the post-IPO period.

Sheet Conclusion
B2: NYKAA IPO ANALYSIS
B4: Conclusion
B6: Business QUESTION | L6: What Went Well | P6: Areas to Watch
B7: Did Nykaa's financial performance justify the premium valuation investors paid during its IPO? | E7: Evidence | L7: • Revenue growth remained strong throughout the analysis period, even after the excitement around the IPO settled down. • The company gradually improved its operating margin, showing better control over its operations. • Cash flow improved significantly, which suggests that the business is becoming financially stronger over time. • Overall, Nykaa continued to expand while maintaining steady financial progress. | P7: • Although profits improved, net profit margins are still relatively low compared to the company's strong revenue growth. • Borrowings increased over the years, so managing debt efficiently will remain important. • As Nykaa grows further, maintaining high growth rates in a competitive beauty and lifestyle market may become more challenging.
E8: Area | F8: Observation | H8: Evidence
E9: Revenue Growth | F9: Strong and consistent growth | H9: Revenue increased from ₹3,774 Cr in FY22 to ₹10,022 Cr in FY26 (≈2.7x growth, 21.6% CAGR).
E11: Profitability | F11: Steady improvement | H11: Operating Margin improved from 4.35% to 7.50%, while Net Profit increased from ₹41 Cr to ₹204 Cr.
E13: Cash Flow | F13: Strong recovery | H13: Operating Cash Flow improved from –₹354 Cr (FY22) to ₹644 Cr (FY26). Free Cash Flow turned positive from FY25.
B14: Final Verdict
B15: Partially Yes | E15: Financial Position | F15: Financial position strengthened, although borrowings increased. | H15: Total Assets grew from ₹2,646 Cr to ₹4,611 Cr, while borrowings also increased to support expansion.
B19: Conclusion | D19: After analyzing Nykaa's financial statements from FY22 to FY26, I believe the company has performed well since its IPO. Revenue has almost tripled, profitability has improved, and cash flows have become much stronger over time. These are all positive signs that the business is moving in the right direction. At the same time, I don't think revenue growth alone is enough to fully justify the premium valuation investors paid during the IPO. The company is still working towards improving its profit margins, and investors would expect those margins to continue improving as the business matures. Overall, I would say Nykaa has partially justified its IPO valuation. The company has built a stronger financial position after listing, but there is still scope to improve profitability and create greater value for shareholders over the long term.
